<?xml version="1.0" encoding="UTF-8"?>
<testng-results skipped="0" failed="1" ignored="0" total="2" passed="1">
  <reporter-output>
  </reporter-output>
  <suite name="Suite" duration-ms="14177" started-at="2019-07-02T21:26:39Z" finished-at="2019-07-02T21:26:53Z">
    <groups>
    </groups>
    <test name="sel-test-listner" duration-ms="14177" started-at="2019-07-02T21:26:39Z" finished-at="2019-07-02T21:26:53Z">
      <class name="TestNG.Listner.TestClass">
        <test-method status="PASS" signature="testClassBegin()[pri:0, instance:TestNG.Listner.TestClass@cd072c]" name="testClassBegin" is-config="true" duration-ms="14" started-at="2019-07-02T21:26:39Z" finished-at="2019-07-02T21:26:39Z">
          <reporter-output>
          </reporter-output>
        </test-method> <!-- testClassBegin -->
        <test-method status="PASS" signature="Login()[pri:0, instance:TestNG.Listner.TestClass@cd072c]" name="Login" duration-ms="14106" started-at="2019-07-02T21:26:39Z" finished-at="2019-07-02T21:26:53Z">
          <reporter-output>
          </reporter-output>
        </test-method> <!-- Login -->
        <test-method status="FAIL" signature="TestFail()[pri:0, instance:TestNG.Listner.TestClass@cd072c]" name="TestFail" duration-ms="4" started-at="2019-07-02T21:26:53Z" finished-at="2019-07-02T21:26:53Z">
          <exception class="java.lang.AssertionError">
            <message>
              <![CDATA[expected [true] but found [false]]]>
            </message>
            <full-stacktrace>
              <![CDATA[java.lang.AssertionError: expected [true] but found [false]
at org.testng.Assert.fail(Assert.java:96)
at org.testng.Assert.failNotEquals(Assert.java:776)
at org.testng.Assert.assertTrue(Assert.java:44)
at org.testng.Assert.assertTrue(Assert.java:54)
at TestNG.Listner.TestClass.TestFail(TestClass.java:40)
at sun.reflect.NativeMethodAccessorImpl.invoke0(Native Method)
at sun.reflect.NativeMethodAccessorImpl.invoke(Unknown Source)
at sun.reflect.DelegatingMethodAccessorImpl.invoke(Unknown Source)
at java.lang.reflect.Method.invoke(Unknown Source)
at org.testng.internal.MethodInvocationHelper.invokeMethod(MethodInvocationHelper.java:124)
at org.testng.internal.Invoker.invokeMethod(Invoker.java:583)
at org.testng.internal.Invoker.invokeTestMethod(Invoker.java:719)
at org.testng.internal.Invoker.invokeTestMethods(Invoker.java:989)
at org.testng.internal.TestMethodWorker.invokeTestMethods(TestMethodWorker.java:125)
at org.testng.internal.TestMethodWorker.run(TestMethodWorker.java:109)
at org.testng.TestRunner.privateRun(TestRunner.java:648)
at org.testng.TestRunner.run(TestRunner.java:505)
at org.testng.SuiteRunner.runTest(SuiteRunner.java:455)
at org.testng.SuiteRunner.runSequentially(SuiteRunner.java:450)
at org.testng.SuiteRunner.privateRun(SuiteRunner.java:415)
at org.testng.SuiteRunner.run(SuiteRunner.java:364)
at org.testng.SuiteRunnerWorker.runSuite(SuiteRunnerWorker.java:52)
at org.testng.SuiteRunnerWorker.run(SuiteRunnerWorker.java:84)
at org.testng.TestNG.runSuitesSequentially(TestNG.java:1208)
at org.testng.TestNG.runSuitesLocally(TestNG.java:1137)
at org.testng.TestNG.runSuites(TestNG.java:1049)
at org.testng.TestNG.run(TestNG.java:1017)
at org.testng.remote.AbstractRemoteTestNG.run(AbstractRemoteTestNG.java:115)
at org.testng.remote.RemoteTestNG.initAndRun(RemoteTestNG.java:251)
at org.testng.remote.RemoteTestNG.main(RemoteTestNG.java:77)
]]>
            </full-stacktrace>
          </exception> <!-- java.lang.AssertionError -->
          <reporter-output>
          </reporter-output>
        </test-method> <!-- TestFail -->
        <test-method status="PASS" signature="testClassEnd()[pri:0, instance:TestNG.Listner.TestClass@cd072c]" name="testClassEnd" is-config="true" duration-ms="0" started-at="2019-07-02T21:26:53Z" finished-at="2019-07-02T21:26:53Z">
          <reporter-output>
          </reporter-output>
        </test-method> <!-- testClassEnd -->
      </class> <!-- TestNG.Listner.TestClass -->
    </test> <!-- sel-test-listner -->
  </suite> <!-- Suite -->
</testng-results>
